Workbook

Sheet Estado_cepas
A1: Codigo | B1: Extracción ADN | C1: PCRs | D1: Secuenciación | E1: Proyecto | F1: FECHA INICIO | G1: Organismo
A2: 1 Tif DNAa 16S 1/3 | B2: {=IFERROR( IF(INDEX([1]Extraídas!B:B,MATCH(LEFT($A2,6)&"*",[1]Extraídas!A:A,0))="Extraídas", "✅ En proceso", IF(INDEX([1]Extraídas!B:B,MATCH(LEFT($A2,6)&"*",[1]Extraídas!A:A,0))="Recibidas", "⏳ Pendiente","❌ No ingresada")), "❌ No ingresada" )} -> ✅ En proceso | C2: {=IFERROR( IF(INDEX([1]PCRs!B:B,MATCH(LEFT($A2,6)&"*",[1]PCRs!A:A,0))="Positivo", "✅ Positivo", IF(INDEX([1]PCRs!B:B,MATCH(LEFT($A2,6)&"*",[1]PCRs!A:A,0))="Negativo", "❌ Negativo", "⏳ No realizado")), "⏳ No realizado" )} -> ⏳ No realizado | D2: =IFERROR( CHOOSE( MATCH(VLOOKUP(LEFT(A49,6)&"*",'Identificación genética'!A:C,2,FALSE), {"En proceso";"Finalizado"},0), "🔬 En proceso", "🎯 Finalizado" ), "❌ NA") -> ❌ NA | E2: Algasal | F2: 45947 | G2: =_xlfn.XLOOKUP(A2, Extraídas!A:A, Extraídas!G:G, "") -> ambiental
A3: 1 Tif DNAa 16S 2/3 | B3: {=IFERROR( IF(INDEX([1]Extraídas!B:B,MATCH(LEFT($A3,6)&"*",[1]Extraídas!A:A,0))="Extraídas", "✅ En proceso", IF(INDEX([1]Extraídas!B:B,MATCH(LEFT($A3,6)&"*",[1]Extraídas!A:A,0))="Recibidas", "⏳ Pendiente","❌ No ingresada")), "❌ No ingresada" )} -> ✅ En proceso | C3: {=IFERROR( IF(INDEX([1]PCRs!B:B,MATCH(LEFT($A3,6)&"*",[1]PCRs!A:A,0))="Positivo", "✅ Positivo", IF(INDEX([1]PCRs!B:B,MATCH(LEFT($A3,6)&"*",[1]PCRs!A:A,0))="Negativo", "❌ Negativo", "⏳ No realizado")), "⏳ No realizado" )} -> ⏳ No realizado | D3: =IFERROR( CHOOSE( MATCH(VLOOKUP(LEFT(A50,6)&"*",'Identificación genética'!A:C,2,FALSE), {"En proceso";"Finalizado"},0), "🔬 En proceso", "🎯 Finalizado" ), "❌ NA") -> ❌ NA | E3: Algasal | F3: 45947 | G3: =_xlfn.XLOOKUP(A3, Extraídas!A:A, Extraídas!G:G, "") -> ambiental
A4: 1 Tif DNAa 16S 3/3 | B4: {=IFERROR( IF(INDEX([1]Extraídas!B:B,MATCH(LEFT($A4,6)&"*",[1]Extraídas!A:A,0))="Extraídas", "✅ En proceso", IF(INDEX([1]Extraídas!B:B,MATCH(LEFT($A4,6)&"*",[1]Extraídas!A:A,0))="Recibidas", "⏳ Pendiente","❌ No ingresada")), "❌ No ingresada" )} -> ✅ En proceso | C4: {=IFERROR( IF(INDEX([1]PCRs!B:B,MATCH(LEFT($A4,6)&"*",[1]PCRs!A:A,0))="Positivo", "✅ Positivo", IF(INDEX([1]PCRs!B:B,MATCH(LEFT($A4,6)&"*",[1]PCRs!A:A,0))="Negativo", "❌ Negativo", "⏳ No realizado")), "⏳ No realizado" )} -> ⏳ No realizado | D4: =IFERROR( CHOOSE( MATCH(VLOOKUP(LEFT(A51,6)&"*",'Identificación genética'!A:C,2,FALSE), {"En proceso";"Finalizado"},0), "🔬 En proceso", "🎯 Finalizado" ), "❌ NA") -> ❌ NA | E4: Algasal | F4: 45947 | G4: =_xlfn.XLOOKUP(A4, Extraídas!A:A, Extraídas!G:G, "") -> ambiental
A5: 1.1_MARZO_ALGASAL | B5: =IFERROR( IF(INDEX(Extraídas!B:B,MATCH(LEFT($A5,6)&"*",Extraídas!A:A,0))="Extraídas", "✅ En proceso", IF(INDEX(Extraídas!B:B,MATCH(LEFT($A5,6)&"*",Extraídas!A:A,0))="Recibidas", "⏳ Pendiente","❌ No ingresada")), "❌ No ingresada" ) -> ✅ En proceso | C5: {=IFERROR( IF(INDEX([1]PCRs!B:B,MATCH(LEFT($A5,6)&"*",[1]PCRs!A:A,0))="Positivo", "✅ Positivo", IF(INDEX([1]PCRs!B:B,MATCH(LEFT($A5,6)&"*",[1]PCRs!A:A,0))="Negativo", "❌ Negativo", "⏳ No realizado")), "⏳ No realizado" )} -> ❌ Negativo | D5: =IFERROR( CHOOSE( MATCH(VLOOKUP(LEFT(A52,6)&"*",'Identificación genética'!A:C,2,FALSE), {"En proceso";"Finalizado"},0), "🔬 En proceso", "🎯 Finalizado" ), "❌ NA") -> ❌ NA | E5: Algasal | F5: 45756 | G5: =_xlfn.XLOOKUP(A5, Extraídas!A:A, Extraídas!G:G, "") -> Macroalgas
A6: 1.1RP7 | B6: {=IFERROR( IF(INDEX([1]Extraídas!B:B,MATCH(LEFT($A6,6)&"*",[1]Extraídas!A:A,0))="Extraídas", "✅ En proceso", IF(INDEX([1]Extraídas!B:B,MATCH(LEFT($A6,6)&"*",[1]Extraídas!A:A,0))="Recibidas", "⏳ Pendiente","❌ No ingresada")), "❌ No ingresada" )} -> ✅ En proceso | C6: {=IFERROR( IF(INDEX([1]PCRs!B:B,MATCH(LEFT($A6,6)&"*",[1]PCRs!A:A,0))="Positivo", "✅ Positivo", IF(INDEX([1]PCRs!B:B,MATCH(LEFT($A6,6)&"*",[1]PCRs!A:A,0))="Negativo", "❌ Negativo", "⏳ No realizado")), "⏳ No realizado" )} -> ⏳ No realizado | D6: =IFERROR( CHOOSE( MATCH(VLOOKUP(LEFT(A53,6)&"*",'Identificación genética'!A:C,2,FALSE), {"En proceso";"Finalizado"},0), "🔬 En proceso", "🎯 Finalizado" ), "❌ NA") -> ❌ NA | E6: Algasal | F6: 45922 | G6: =_xlfn.XLOOKUP(A6, Extraídas!A:A, Extraídas!G:G, "") -> Macroalgas
A7: 1.2_MARZO_ALGASAL | B7: =IFERROR( IF(INDEX(Extraídas!B:B,MATCH(LEFT($A7,6)&"*",Extraídas!A:A,0))="Extraídas", "✅ En proceso", IF(INDEX(Extraídas!B:B,MATCH(LEFT($A7,6)&"*",Extraídas!A:A,0))="Recibidas", "⏳ Pendiente","❌ No ingresada")), "❌ No ingresada" ) -> ✅ En proceso | C7: {=IFERROR( IF(INDEX([1]PCRs!B:B,MATCH(LEFT($A7,6)&"*",[1]PCRs!A:A,0))="Positivo", "✅ Positivo", IF(INDEX([1]PCRs!B:B,MATCH(LEFT($A7,6)&"*",[1]PCRs!A:A,0))="Negativo", "❌ Negativo", "⏳ No realizado")), "⏳ No realizado" )} -> ⏳ No realizado | D7: =IFERROR( CHOOSE( MATCH(VLOOKUP(LEFT(A54,6)&"*",'Identificación genética'!A:C,2,FALSE), {"En proceso";"Finalizado"},0), "🔬 En proceso", "🎯 Finalizado" ), "❌ NA") -> ❌ NA | E7: Algasal | F7: 45756 | G7: =_xlfn.XLOOKUP(A7, Extraídas!A:A, Extraídas!G:G, "") -> Macroalgas
A8: 1.3_MARZO_ALGASAL | B8: =IFERROR( IF(INDEX(Extraídas!B:B,MATCH(LEFT($A8,6)&"*",Extraídas!A:A,0))="Extraídas", "✅ En proceso", IF(INDEX(Extraídas!B:B,MATCH(LEFT($A8,6)&"*",Extraídas!A:A,0))="Recibidas", "⏳ Pendiente","❌ No ingresada")), "❌ No ingresada" ) -> ✅ En proceso | C8: {=IFERROR( IF(INDEX([1]PCRs!B:B,MATCH(LEFT($A8,6)&"*",[1]PCRs!A:A,0))="Positivo", "✅ Positivo", IF(INDEX([1]PCRs!B:B,MATCH(LEFT($A8,6)&"*",[1]PCRs!A:A,0))="Negativo", "❌ Negativo", "⏳ No realizado")), "⏳ No realizado" )} -> ✅ Positivo | D8: =IFERROR( CHOOSE( MATCH(VLOOKUP(LEFT(A55,6)&"*",'Identificación genética'!A:C,2,FALSE), {"En proceso";"Finalizado"},0), "🔬 En proceso", "🎯 Finalizado" ), "❌ NA") -> ❌ NA | E8: Algasal | F8: 45756 | G8: =_xlfn.XLOOKUP(A8, Extraídas!A:A, Extraídas!G:G, "") -> Macroalgas
A9: 2 Tif DNAa 16S 1/3 | B9: {=IFERROR( IF(INDEX([1]Extraídas!B:B,MATCH(LEFT($A9,6)&"*",[1]Extraídas!A:A,0))="Extraídas", "✅ En proceso", IF(INDEX([1]Extraídas!B:B,MATCH(LEFT($A9,6)&"*",[1]Extraídas!A:A,0))="Recibidas", "⏳ Pendiente","❌ No ingresada")), "❌ No ingresada" )} -> ✅ En proceso | C9: {=IFERROR( IF(INDEX([1]PCRs!B:B,MATCH(LEFT($A9,6)&"*",[1]PCRs!A:A,0))="Positivo", "✅ Positivo", IF(INDEX([1]PCRs!B:B,MATCH(LEFT($A9,6)&"*",[1]PCRs!A:A,0))="Negativo", "❌ Negativo", "⏳ No realizado")), "⏳ No realizado" )} -> ⏳ No realizado | D9: =IFERROR( CHOOSE( MATCH(VLOOKUP(LEFT(A56,6)&"*",'Identificación genética'!A:C,2,FALSE), {"En proceso";"Finalizado"},0), "🔬 En proceso", "🎯 Finalizado" ), "❌ NA") -> ❌ NA | E9: Algasal | F9: 45947 | G9: =_xlfn.XLOOKUP(A9, Extraídas!A:A, Extraídas!G:G, "") -> ambiental
A10: 2 Tif DNAa 16S 2/3 | B10: {=IFERROR( IF(INDEX([1]Extraídas!B:B,MATCH(LEFT($A10,6)&"*",[1]Extraídas!A:A,0))="Extraídas", "✅ En proceso", IF(INDEX([1]Extraídas!B:B,MATCH(LEFT($A10,6)&"*",[1]Extraídas!A:A,0))="Recibidas", "⏳ Pendiente","❌ No ingresada")), "❌ No ingresada" )} -> ✅ En proceso | C10: {=IFERROR( IF(INDEX([1]PCRs!B:B,MATCH(LEFT($A10,6)&"*",[1]PCRs!A:A,0))="Positivo", "✅ Positivo", IF(INDEX([1]PCRs!B:B,MATCH(LEFT($A10,6)&"*",[1]PCRs!A:A,0))="Negativo", "❌ Negativo", "⏳ No realizado")), "⏳ No realizado" )} -> ⏳ No realizado | D10: =IFERROR( CHOOSE( MATCH(VLOOKUP(LEFT(A57,6)&"*",'Identificación genética'!A:C,2,FALSE), {"En proceso";"Finalizado"},0), "🔬 En proceso", "🎯 Finalizado" ), "❌ NA") -> ❌ NA | E10: Algasal | F10: 45947 | G10: =_xlfn.XLOOKUP(A10, Extraídas!A:A, Extraídas!G:G, "") -> ambiental
A11: 2 Tif DNAa 16S 3/3 | B11: {=IFERROR( IF(INDEX([1]Extraídas!B:B,MATCH(LEFT($A11,6)&"*",[1]Extraídas!A:A,0))="Extraídas", "✅ En proceso", IF(INDEX([1]Extraídas!B:B,MATCH(LEFT($A11,6)&"*",[1]Extraídas!A:A,0))="Recibidas", "⏳ Pendiente","❌ No ingresada")), "❌ No ingresada" )} -> ✅ En proceso | C11: {=IFERROR( IF(INDEX([1]PCRs!B:B,MATCH(LEFT($A11,6)&"*",[1]PCRs!A:A,0))="Positivo", "✅ Positivo", IF(INDEX([1]PCRs!B:B,MATCH(LEFT($A11,6)&"*",[1]PCRs!A:A,0))="Negativo", "❌ Negativo", "⏳ No realizado")), "⏳ No realizado" )} -> ⏳ No realizado | D11: =IFERROR( CHOOSE( MATCH(VLOOKUP(LEFT(A58,6)&"*",'Identificación genética'!A:C,2,FALSE), {"En proceso";"Finalizado"},0), "🔬 En proceso", "🎯 Finalizado" ), "❌ NA") -> ❌ NA | E11: Algasal | F11: 45947 | G11: =_xlfn.XLOOKUP(A11, Extraídas!A:A, Extraídas!G:G, "") -> ambiental
A12: 2.1 RP9 | B12: {=IFERROR( IF(INDEX([1]Extraídas!B:B,MATCH(LEFT($A12,6)&"*",[1]Extraídas!A:A,0))="Extraídas", "✅ En proceso", IF(INDEX([1]Extraídas!B:B,MATCH(LEFT($A12,6)&"*",[1]Extraídas!A:A,0))="Recibidas", "⏳ Pendiente","❌ No ingresada")), "❌ No ingresada" )} -> ✅ En proceso | C12: {=IFERROR( IF(INDEX([1]PCRs!B:B,MATCH(LEFT($A12,6)&"*",[1]PCRs!A:A,0))="Positivo", "✅ Positivo", IF(INDEX([1]PCRs!B:B,MATCH(LEFT($A12,6)&"*",[1]PCRs!A:A,0))="Negativo", "❌ Negativo", "⏳ No realizado")), "⏳ No realizado" )} -> ⏳ No realizado | D12: =IFERROR( CHOOSE( MATCH(VLOOKUP(LEFT(A59,6)&"*",'Identificación genética'!A:C,2,FALSE), {"En proceso";"Finalizado"},0), "🔬 En proceso", "🎯 Finalizado" ), "❌ NA") -> ❌ NA | E12: Algasal | F12: 45946 | G12: =_xlfn.XLOOKUP(A12, Extraídas!A:A, Extraídas!G:G, "") -> MACROALGAS
A13: 2.1_MARZO_ALGASAL | B13: =IFERROR( IF(INDEX(Extraídas!B:B,MATCH(LEFT($A13,6)&"*",Extraídas!A:A,0))="Extraídas", "✅ En proceso", IF(INDEX(Extraídas!B:B,MATCH(LEFT($A13,6)&"*",Extraídas!A:A,0))="Recibidas", "⏳ Pendiente","❌ No ingresada")), "❌ No ingresada" ) -> ✅ En proceso | C13: {=IFERROR( IF(INDEX([1]PCRs!B:B,MATCH(LEFT($A13,6)&"*",[1]PCRs!A:A,0))="Positivo", "✅ Positivo", IF(INDEX([1]PCRs!B:B,MATCH(LEFT($A13,6)&"*",[1]PCRs!A:A,0))="Negativo", "❌ Negativo", "⏳ No realizado")), "⏳ No realizado" )} -> ⏳ No realizado | D13: =IFERROR( CHOOSE( MATCH(VLOOKUP(LEFT(A60,6)&"*",'Identificación genética'!A:C,2,FALSE), {"En proceso";"Finalizado"},0), "🔬 En proceso", "🎯 Finalizado" ), "❌ NA") -> ❌ NA | E13: Algasal | F13: 45756 | G13: =_xlfn.XLOOKUP(A13, Extraídas!A:A, Extraídas!G:G, "") -> Macroalgas
A14: 2.2 RP9 | B14: {=IFERROR( IF(INDEX([1]Extraídas!B:B,MATCH(LEFT($A14,6)&"*",[1]Extraídas!A:A,0))="Extraídas", "✅ En proceso", IF(INDEX([1]Extraídas!B:B,MATCH(LEFT($A14,6)&"*",[1]Extraídas!A:A,0))="Recibidas", "⏳ Pendiente","❌ No ingresada")), "❌ No ingresada" )} -> ✅ En proceso | C14: {=IFERROR( IF(INDEX([1]PCRs!B:B,MATCH(LEFT($A14,6)&"*",[1]PCRs!A:A,0))="Positivo", "✅ Positivo", IF(INDEX([1]PCRs!B:B,MATCH(LEFT($A14,6)&"*",[1]PCRs!A:A,0))="Negativo", "❌ Negativo", "⏳ No realizado")), "⏳ No realizado" )} -> ⏳ No realizado | D14: =IFERROR( CHOOSE( MATCH(VLOOKUP(LEFT(A61,6)&"*",'Identificación genética'!A:C,2,FALSE), {"En proceso";"Finalizado"},0), "🔬 En proceso", "🎯 Finalizado" ), "❌ NA") -> ❌ NA | E14: Algasal | F14: 45946 | G14: =_xlfn.XLOOKUP(A14, Extraídas!A:A, Extraídas!G:G, "") -> MACROALGAS
A15: 2.2_MARZO_ALGASAL | B15: {=IFERROR( IF(INDEX([1]Extraídas!B:B,MATCH(LEFT($A15,6)&"*",[1]Extraídas!A:A,0))="Extraídas", "✅ En proceso", IF(INDEX([1]Extraídas!B:B,MATCH(LEFT($A15,6)&"*",[1]Extraídas!A:A,0))="Recibidas", "⏳ Pendiente","❌ No ingresada")), "❌ No ingresada" )} -> ✅ En proceso | C15: {=IFERROR( IF(INDEX([1]PCRs!B:B,MATCH(LEFT($A15,6)&"*",[1]PCRs!A:A,0))="Positivo", "✅ Positivo", IF(INDEX([1]PCRs!B:B,MATCH(LEFT($A15,6)&"*",[1]PCRs!A:A,0))="Negativo", "❌ Negativo", "⏳ No realizado")), "⏳ No realizado" )} -> ❌ Negativo | D15: =IFERROR( CHOOSE( MATCH(VLOOKUP(LEFT(A62,6)&"*",'Identificación genética'!A:C,2,FALSE), {"En proceso";"Finalizado"},0), "🔬 En proceso", "🎯 Finalizado" ), "❌ NA") -> ❌ NA | E15: Algasal | F15: 45756 | G15: =_xlfn.XLOOKUP(A15, Extraídas!A:A, Extraídas!G:G, "") -> Macroalgas
A16: 2.2RP7 | B16: {=IFERROR( IF(INDEX([1]Extraídas!B:B,MATCH(LEFT($A16,6)&"*",[1]Extraídas!A:A,0))="Extraídas", "✅ En proceso", IF(INDEX([1]Extraídas!B:B,MATCH(LEFT($A16,6)&"*",[1]Extraídas!A:A,0))="Recibidas", "⏳ Pendiente","❌ No ingresada")), "❌ No ingresada" )} -> ✅ En proceso | C16: {=IFERROR( IF(INDEX([1]PCRs!B:B,MATCH(LEFT($A16,6)&"*",[1]PCRs!A:A,0))="Positivo", "✅ Positivo", IF(INDEX([1]PCRs!B:B,MATCH(LEFT($A16,6)&"*",[1]PCRs!A:A,0))="Negativo", "❌ Negativo", "⏳ No realizado")), "⏳ No realizado" )} -> ⏳ No realizado | D16: =IFERROR( CHOOSE( MATCH(VLOOKUP(LEFT(A63,6)&"*",'Identificación genética'!A:C,2,FALSE), {"En proceso";"Finalizado"},0), "🔬 En proceso", "🎯 Finalizado" ), "❌ NA") -> ❌ NA | E16: Algasal | F16: 45922 | G16: =_xlfn.XLOOKUP(A16, Extraídas!A:A, Extraídas!G:G, "") -> Macroalgas
A17: 2.3 RP9 | B17: {=IFERROR( IF(INDEX([1]Extraídas!B:B,MATCH(LEFT($A17,6)&"*",[1]Extraídas!A:A,0))="Extraídas", "✅ En proceso", IF(INDEX([1]Extraídas!B:B,MATCH(LEFT($A17,6)&"*",[1]Extraídas!A:A,0))="Recibidas", "⏳ Pendiente","❌ No ingresada")), "❌ No ingresada" )} -> ✅ En proceso | C17: {=IFERROR( IF(INDEX([1]PCRs!B:B,MATCH(LEFT($A17,6)&"*",[1]PCRs!A:A,0))="Positivo", "✅ Positivo", IF(INDEX([1]PCRs!B:B,MATCH(LEFT($A17,6)&"*",[1]PCRs!A:A,0))="Negativo", "❌ Negativo", "⏳ No realizado")), "⏳ No realizado" )} -> ⏳ No realizado | D17: =IFERROR( CHOOSE( MATCH(VLOOKUP(LEFT(A64,6)&"*",'Identificación genética'!A:C,2,FALSE), {"En proceso";"Finalizado"},0), "🔬 En proceso", "🎯 Finalizado" ), "❌ NA") -> ❌ NA | E17: Algasal | F17: 45946 | G17: =_xlfn.XLOOKUP(A17, Extraídas!A:A, Extraídas!G:G, "") -> MACROALGAS
A18: 2.3_MARZO_ALGASAL | B18: {=IFERROR( IF(INDEX([1]Extraídas!B:B,MATCH(LEFT($A18,6)&"*",[1]Extraídas!A:A,0))="Extraídas", "✅ En proceso", IF(INDEX([1]Extraídas!B:B,MATCH(LEFT($A18,6)&"*",[1]Extraídas!A:A,0))="Recibidas", "⏳ Pendiente","❌ No ingresada")), "❌ No ingresada" )} -> ✅ En proceso | C18: {=IFERROR( IF(INDEX([1]PCRs!B:B,MATCH(LEFT($A18,6)&"*",[1]PCRs!A:A,0))="Positivo", "✅ Positivo", IF(INDEX([1]PCRs!B:B,MATCH(LEFT($A18,6)&"*",[1]PCRs!A:A,0))="Negativo", "❌ Negativo", "⏳ No realizado")), "⏳ No realizado" )} -> ❌ Negativo | D18: =IFERROR( CHOOSE( MATCH(VLOOKUP(LEFT(A65,6)&"*",'Identificación genética'!A:C,2,FALSE), {"En proceso";"Finalizado"},0), "🔬 En proceso", "🎯 Finalizado" ), "❌ NA") -> ❌ NA | E18: Algasal | F18: 45756 | G18: =_xlfn.XLOOKUP(A18, Extraídas!A:A, Extraídas!G:G, "") -> Macroalgas
A19: 2.3RP7 | B19: {=IFERROR( IF(INDEX([1]Extraídas!B:B,MATCH(LEFT($A19,6)&"*",[1]Extraídas!A:A,0))="Extraídas", "✅ En proceso", IF(INDEX([1]Extraídas!B:B,MATCH(LEFT($A19,6)&"*",[1]Extraídas!A:A,0))="Recibidas", "⏳ Pendiente","❌ No ingresada")), "❌ No ingresada" )} -> ✅ En proceso | C19: {=IFERROR( IF(INDEX([1]PCRs!B:B,MATCH(LEFT($A19,6)&"*",[1]PCRs!A:A,0))="Positivo", "✅ Positivo", IF(INDEX([1]PCRs!B:B,MATCH(LEFT($A19,6)&"*",[1]PCRs!A:A,0))="Negativo", "❌ Negativo", "⏳ No realizado")), "⏳ No realizado" )} -> ⏳ No realizado | D19: =IFERROR( CHOOSE( MATCH(VLOOKUP(LEFT(A66,6)&"*",'Identificación genética'!A:C,2,FALSE), {"En proceso";"Finalizado"},0), "🔬 En proceso", "🎯 Finalizado" ), "❌ NA") -> ❌ NA | E19: Algasal | F19: 45922 | G19: =_xlfn.XLOOKUP(A19, Extraídas!A:A, Extraídas!G:G, "") -> Macroalgas
A20: 2.4 RP9 | B20: {=IFERROR( IF(INDEX([1]Extraídas!B:B,MATCH(LEFT($A20,6)&"*",[1]Extraídas!A:A,0))="Extraídas", "✅ En proceso", IF(INDEX([1]Extraídas!B:B,MATCH(LEFT($A20,6)&"*",[1]Extraídas!A:A,0))="Recibidas", "⏳ Pendiente","❌ No ingresada")), "❌ No ingresada" )} -> ✅ En proceso | C20: {=IFERROR( IF(INDEX([1]PCRs!B:B,MATCH(LEFT($A20,6)&"*",[1]PCRs!A:A,0))="Positivo", "✅ Positivo", IF(INDEX([1]PCRs!B:B,MATCH(LEFT($A20,6)&"*",[1]PCRs!A:A,0))="Negativo", "❌ Negativo", "⏳ No realizado")), "⏳ No realizado" )} -> ⏳ No realizado | D20: =IFERROR( CHOOSE( MATCH(VLOOKUP(LEFT(A67,6)&"*",'Identificación genética'!A:C,2,FALSE), {"En proceso";"Finalizado"},0), "🔬 En proceso", "🎯 Finalizado" ), "❌ NA") -> ❌ NA | E20: Algasal | F20: 45946 | G20: =_xlfn.XLOOKUP(A20, Extraídas!A:A, Extraídas!G:G, "") -> MACROALGAS
A21: 2.4RP7 | B21: {=IFERROR( IF(INDEX([1]Extraídas!B:B,MATCH(LEFT($A21,6)&"*",[1]Extraídas!A:A,0))="Extraídas", "✅ En proceso", IF(INDEX([1]Extraídas!B:B,MATCH(LEFT($A21,6)&"*",[1]Extraídas!A:A,0))="Recibidas", "⏳ Pendiente","❌ No ingresada")), "❌ No ingresada" )} -> ✅ En proceso | C21: {=IFERROR( IF(INDEX([1]PCRs!B:B,MATCH(LEFT($A21,6)&"*",[1]PCRs!A:A,0))="Positivo", "✅ Positivo", IF(INDEX([1]PCRs!B:B,MATCH(LEFT($A21,6)&"*",[1]PCRs!A:A,0))="Negativo", "❌ Negativo", "⏳ No realizado")), "⏳ No realizado" )} -> ⏳ No realizado | D21: =IFERROR( CHOOSE( MATCH(VLOOKUP(LEFT(A68,6)&"*",'Identificación genética'!A:C,2,FALSE), {"En proceso";"Finalizado"},0), "🔬 En proceso", "🎯 Finalizado" ), "❌ NA") -> ❌ NA | E21: Algasal | F21: 45922 | G21: =_xlfn.XLOOKUP(A21, Extraídas!A:A, Extraídas!G:G, "") -> Macroalgas
A22: 2.5RP7 | B22: {=IFERROR( IF(INDEX([1]Extraídas!B:B,MATCH(LEFT($A22,6)&"*",[1]Extraídas!A:A,0))="Extraídas", "✅ En proceso", IF(INDEX([1]Extraídas!B:B,MATCH(LEFT($A22,6)&"*",[1]Extraídas!A:A,0))="Recibidas", "⏳ Pendiente","❌ No ingresada")), "❌ No ingresada" )} -> ✅ En proceso | C22: {=IFERROR( IF(INDEX([1]PCRs!B:B,MATCH(LEFT($A22,6)&"*",[1]PCRs!A:A,0))="Positivo", "✅ Positivo", IF(INDEX([1]PCRs!B:B,MATCH(LEFT($A22,6)&"*",[1]PCRs!A:A,0))="Negativo", "❌ Negativo", "⏳ No realizado")), "⏳ No realizado" )} -> ⏳ No realizado | D22: =IFERROR( CHOOSE( MATCH(VLOOKUP(LEFT(A69,6)&"*",'Identificación genética'!A:C,2,FALSE), {"En proceso";"Finalizado"},0), "🔬 En proceso", "🎯 Finalizado" ), "❌ NA") -> ❌ NA | E22: Algasal | F22: 45922 | G22: =_xlfn.XLOOKUP(A22, Extraídas!A:A, Extraídas!G:G, "") -> Macroalgas
A23: 3.1 RP9 | B23: {=IFERROR( IF(INDEX([1]Extraídas!B:B,MATCH(LEFT($A23,6)&"*",[1]Extraídas!A:A,0))="Extraídas", "✅ En proceso", IF(INDEX([1]Extraídas!B:B,MATCH(LEFT($A23,6)&"*",[1]Extraídas!A:A,0))="Recibidas", "⏳ Pendiente","❌ No ingresada")), "❌ No ingresada" )} -> ✅ En proceso | C23: {=IFERROR( IF(INDEX([1]PCRs!B:B,MATCH(LEFT($A23,6)&"*",[1]PCRs!A:A,0))="Positivo", "✅ Positivo", IF(INDEX([1]PCRs!B:B,MATCH(LEFT($A23,6)&"*",[1]PCRs!A:A,0))="Negativo", "❌ Negativo", "⏳ No realizado")), "⏳ No realizado" )} -> ⏳ No realizado | D23: =IFERROR( CHOOSE( MATCH(VLOOKUP(LEFT(A70,6)&"*",'Identificación genética'!A:C,2,FALSE), {"En proceso";"Finalizado"},0), "🔬 En proceso", "🎯 Finalizado" ), "❌ NA") -> ❌ NA | E23: Algasal | F23: 45946 | G23: =_xlfn.XLOOKUP(A23, Extraídas!A:A, Extraídas!G:G, "") -> MACROALGAS
A24: 3.1_MARZO_ALGASAL | B24: {=IFERROR( IF(INDEX([1]Extraídas!B:B,MATCH(LEFT($A24,6)&"*",[1]Extraídas!A:A,0))="Extraídas", "✅ En proceso", IF(INDEX([1]Extraídas!B:B,MATCH(LEFT($A24,6)&"*",[1]Extraídas!A:A,0))="Recibidas", "⏳ Pendiente","❌ No ingresada")), "❌ No ingresada" )} -> ✅ En proceso | C24: {=IFERROR( IF(INDEX([1]PCRs!B:B,MATCH(LEFT($A24,6)&"*",[1]PCRs!A:A,0))="Positivo", "✅ Positivo", IF(INDEX([1]PCRs!B:B,MATCH(LEFT($A24,6)&"*",[1]PCRs!A:A,0))="Negativo", "❌ Negativo", "⏳ No realizado")), "⏳ No realizado" )} -> ❌ Negativo | D24: =IFERROR( CHOOSE( MATCH(VLOOKUP(LEFT(A71,6)&"*",'Identificación genética'!A:C,2,FALSE), {"En proceso";"Finalizado"},0), "🔬 En proceso", "🎯 Finalizado" ), "❌ NA") -> ❌ NA | E24: Algasal | F24: 45756 | G24: =_xlfn.XLOOKUP(A24, Extraídas!A:A, Extraídas!G:G, "") -> Macroalgas
A25: 3.2 RP9 | B25: {=IFERROR( IF(INDEX([1]Extraídas!B:B,MATCH(LEFT($A25,6)&"*",[1]Extraídas!A:A,0))="Extraídas", "✅ En proceso", IF(INDEX([1]Extraídas!B:B,MATCH(LEFT($A25,6)&"*",[1]Extraídas!A:A,0))="Recibidas", "⏳ Pendiente","❌ No ingresada")), "❌ No ingresada" )} -> ✅ En proceso | C25: {=IFERROR( IF(INDEX([1]PCRs!B:B,MATCH(LEFT($A25,6)&"*",[1]PCRs!A:A,0))="Positivo", "✅ Positivo", IF(INDEX([1]PCRs!B:B,MATCH(LEFT($A25,6)&"*",[1]PCRs!A:A,0))="Negativo", "❌ Negativo", "⏳ No realizado")), "⏳ No realizado" )} -> ⏳ No realizado | D25: =IFERROR( CHOOSE( MATCH(VLOOKUP(LEFT(A72,6)&"*",'Identificación genética'!A:C,2,FALSE), {"En proceso";"Finalizado"},0), "🔬 En proceso", "🎯 Finalizado" ), "❌ NA") -> ❌ NA | E25: CALYPSO | F25: 45946 | G25: =_xlfn.XLOOKUP(A25, Extraídas!A:A, Extraídas!G:G, "") -> MACROALGAS
... A32: 3.6RP7 | B32: {=IFERROR( IF(INDEX([1]Extraídas!B:B,MATCH(LEFT($A32,6)&"*",[1]Extraídas!A:A,0))="Extraídas", "✅ En proceso", IF(INDEX([1]Extraídas!B:B,MATCH(LEFT($A32,6)&"*",[1]Extraídas!A:A,0))="Recibidas", "⏳ Pendiente","❌ No ingresada")), "❌ No ingresada" )} -> ✅ En proceso | C32: {=IFERROR( IF(INDEX([1]PCRs!B:B,MATCH(LEFT($A32,6)&"*",[1]PCRs!A:A,0))="Positivo", "✅ Positivo", IF(INDEX([1]PCRs!B:B,MATCH(LEFT($A32,6)&"*",[1]PCRs!A:A,0))="Negativo", "❌ Negativo", "⏳ No realizado")), "⏳ No realizado" )} -> ⏳ No realizado | D32: =IFERROR( CHOOSE( MATCH(VLOOKUP(LEFT(A79,6)&"*",'Identificación genética'!A:C,2,FALSE), {"En proceso";"Finalizado"},0), "🔬 En proceso", "🎯 Finalizado" ), "❌ NA") -> ❌ NA | E32: CALYPSO | F32: 45922 | G32: =_xlfn.XLOOKUP(A32, Extraídas!A:A, Extraídas!G:G, "") -> Macroalgas
A33: A1.1_EUKA | B33: =IFERROR( IF(INDEX(Extraídas!B:B,MATCH(LEFT($A33,6)&"*",Extraídas!A:A,0))="Extraídas", "✅ En proceso", IF(INDEX(Extraídas!B:B,MATCH(LEFT($A33,6)&"*",Extraídas!A:A,0))="Recibidas", "⏳ Pendiente","❌ No ingresada")), "❌ No ingresada" ) -> ✅ En proceso | C33: {=IFERROR( IF(INDEX([1]PCRs!B:B,MATCH(LEFT($A33,6)&"*",[1]PCRs!A:A,0))="Positivo", "✅ Positivo", IF(INDEX([1]PCRs!B:B,MATCH(LEFT($A33,6)&"*",[1]PCRs!A:A,0))="Negativo", "❌ Negativo", "⏳ No realizado")), "⏳ No realizado" )} -> ✅ Positivo | D33: =IFERROR( CHOOSE( MATCH(VLOOKUP(LEFT(A80,6)&"*",'Identificación genética'!A:C,2,FALSE), {"En proceso";"Finalizado"},0), "🔬 En proceso", "🎯 Finalizado" ), "❌ NA") -> ❌ NA | E33: CALYPSO | F33: 45756 | G33: =_xlfn.XLOOKUP(A33, Extraídas!A:A, Extraídas!G:G, "") -> Macroalgas
A34: A1.2_EUKA | B34: =IFERROR( IF(INDEX(Extraídas!B:B,MATCH(LEFT($A34,6)&"*",Extraídas!A:A,0))="Extraídas", "✅ En proceso", IF(INDEX(Extraídas!B:B,MATCH(LEFT($A34,6)&"*",Extraídas!A:A,0))="Recibidas", "⏳ Pendiente","❌ No ingresada")), "❌ No ingresada" ) -> ✅ En proceso | C34: {=IFERROR( IF(INDEX([1]PCRs!B:B,MATCH(LEFT($A34,6)&"*",[1]PCRs!A:A,0))="Positivo", "✅ Positivo", IF(INDEX([1]PCRs!B:B,MATCH(LEFT($A34,6)&"*",[1]PCRs!A:A,0))="Negativo", "❌ Negativo", "⏳ No realizado")), "⏳ No realizado" )} -> ✅ Positivo | D34: =IFERROR( CHOOSE( MATCH(VLOOKUP(LEFT(A81,6)&"*",'Identificación genética'!A:C,2,FALSE), {"En proceso";"Finalizado"},0), "🔬 En proceso", "🎯 Finalizado" ), "❌ NA") -> ❌ NA | E34: CALYPSO | F34: 45756 | G34: =_xlfn.XLOOKUP(A34, Extraídas!A:A, Extraídas!G:G, "") -> Macroalgas
A35: A1.3_EUKA | B35: =IFERROR( IF(INDEX(Extraídas!B:B,MATCH(LEFT($A35,6)&"*",Extraídas!A:A,0))="Extraídas", "✅ En proceso", IF(INDEX(Extraídas!B:B,MATCH(LEFT($A35,6)&"*",Extraídas!A:A,0))="Recibidas", "⏳ Pendiente","❌ No ingresada")), "❌ No ingresada" ) -> ✅ En proceso | C35: {=IFERROR( IF(INDEX([1]PCRs!B:B,MATCH(LEFT($A35,6)&"*",[1]PCRs!A:A,0))="Positivo", "✅ Positivo", IF(INDEX([1]PCRs!B:B,MATCH(LEFT($A35,6)&"*",[1]PCRs!A:A,0))="Negativo", "❌ Negativo", "⏳ No realizado")), "⏳ No realizado" )} -> ✅ Positivo | D35: =IFERROR( CHOOSE( MATCH(VLOOKUP(LEFT(A82,6)&"*",'Identificación genética'!A:C,2,FALSE), {"En proceso";"Finalizado"},0), "🔬 En proceso", "🎯 Finalizado" ), "❌ NA") -> ❌ NA | E35: CALYPSO | F35: 45756 | G35: =_xlfn.XLOOKUP(A35, Extraídas!A:A, Extraídas!G:G, "") -> Macroalgas
A36: A2.1_EUKA | B36: =IFERROR( IF(INDEX(Extraídas!B:B,MATCH(LEFT($A36,6)&"*",Extraídas!A:A,0))="Extraídas", "✅ En proceso", IF(INDEX(Extraídas!B:B,MATCH(LEFT($A36,6)&"*",Extraídas!A:A,0))="Recibidas", "⏳ Pendiente","❌ No ingresada")), "❌ No ingresada" ) -> ✅ En proceso | C36: {=IFERROR( IF(INDEX([1]PCRs!B:B,MATCH(LEFT($A36,6)&"*",[1]PCRs!A:A,0))="Positivo", "✅ Positivo", IF(INDEX([1]PCRs!B:B,MATCH(LEFT($A36,6)&"*",[1]PCRs!A:A,0))="Negativo", "❌ Negativo", "⏳ No realizado")), "⏳ No realizado" )} -> ✅ Positivo | D36: =IFERROR( CHOOSE( MATCH(VLOOKUP(LEFT(A83,6)&"*",'Identificación genética'!A:C,2,FALSE), {"En proceso";"Finalizado"},0), "🔬 En proceso", "🎯 Finalizado" ), "❌ NA") -> ❌ NA | E36: CALYPSO | F36: 45756 | G36: =_xlfn.XLOOKUP(A36, Extraídas!A:A, Extraídas!G:G, "") -> Macroalgas
A37: A2.2_EUKA | B37: =IFERROR( IF(INDEX(Extraídas!B:B,MATCH(LEFT($A37,6)&"*",Extraídas!A:A,0))="Extraídas", "✅ En proceso", IF(INDEX(Extraídas!B:B,MATCH(LEFT($A37,6)&"*",Extraídas!A:A,0))="Recibidas", "⏳ Pendiente","❌ No ingresada")), "❌ No ingresada" ) -> ✅ En proceso | C37: {=IFERROR( IF(INDEX([1]PCRs!B:B,MATCH(LEFT($A37,6)&"*",[1]PCRs!A:A,0))="Positivo", "✅ Positivo", IF(INDEX([1]PCRs!B:B,MATCH(LEFT($A37,6)&"*",[1]PCRs!A:A,0))="Negativo", "❌ Negativo", "⏳ No realizado")), "⏳ No realizado" )} -> ❌ Negativo | D37: =IFERROR( CHOOSE( MATCH(VLOOKUP(LEFT(A84,6)&"*",'Identificación genética'!A:C,2,FALSE), {"En proceso";"Finalizado"},0), "🔬 En proceso", "🎯 Finalizado" ), "❌ NA") -> ❌ NA | E37: CALYPSO | F37: 45756 | G37: =_xlfn.XLOOKUP(A37, Extraídas!A:A, Extraídas!G:G, "") -> Macroalgas
A38: A3.1_EUKA | B38: =IFERROR( IF(INDEX(Extraídas!B:B,MATCH(LEFT($A38,6)&"*",Extraídas!A:A,0))="Extraídas", "✅ En proceso", IF(INDEX(Extraídas!B:B,MATCH(LEFT($A38,6)&"*",Extraídas!A:A,0))="Recibidas", "⏳ Pendiente","❌ No ingresada")), "❌ No ingresada" ) -> ✅ En proceso | C38: {=IFERROR( IF(INDEX([1]PCRs!B:B,MATCH(LEFT($A38,6)&"*",[1]PCRs!A:A,0))="Positivo", "✅ Positivo", IF(INDEX([1]PCRs!B:B,MATCH(LEFT($A38,6)&"*",[1]PCRs!A:A,0))="Negativo", "❌ Negativo", "⏳ No realizado")), "⏳ No realizado" )} -> ❌ Negativo | D38: =IFERROR( CHOOSE( MATCH(VLOOKUP(LEFT(A85,6)&"*",'Identificación genética'!A:C,2,FALSE), {"En proceso";"Finalizado"},0), "🔬 En proceso", "🎯 Finalizado" ), "❌ NA") -> ❌ NA | E38: CALYPSO | F38: 45756 | G38: =_xlfn.XLOOKUP(A38, Extraídas!A:A, Extraídas!G:G, "") -> Macroalgas
A39: A3.2_EUKA | B39: =IFERROR( IF(INDEX(Extraídas!B:B,MATCH(LEFT($A39,6)&"*",Extraídas!A:A,0))="Extraídas", "✅ En proceso", IF(INDEX(Extraídas!B:B,MATCH(LEFT($A39,6)&"*",Extraídas!A:A,0))="Recibidas", "⏳ Pendiente","❌ No ingresada")), "❌ No ingresada" ) -> ✅ En proceso | C39: {=IFERROR( IF(INDEX([1]PCRs!B:B,MATCH(LEFT($A39,6)&"*",[1]PCRs!A:A,0))="Positivo", "✅ Positivo", IF(INDEX([1]PCRs!B:B,MATCH(LEFT($A39,6)&"*",[1]PCRs!A:A,0))="Negativo", "❌ Negativo", "⏳ No realizado")), "⏳ No realizado" )} -> ✅ Positivo | D39: =IFERROR( CHOOSE( MATCH(VLOOKUP(LEFT(A86,6)&"*",'Identificación genética'!A:C,2,FALSE), {"En proceso";"Finalizado"},0), "🔬 En proceso", "🎯 Finalizado" ), "❌ NA") -> ❌ NA | E39: CALYPSO | F39: 45756 | G39: =_xlfn.XLOOKUP(A39, Extraídas!A:A, Extraídas!G:G, "") -> Macroalgas
A40: Agüimes 1 | B40: {=IFERROR( IF(INDEX([1]Extraídas!B:B,MATCH(LEFT($A40,6)&"*",[1]Extraídas!A:A,0))="Extraídas", "✅ En proceso", IF(INDEX([1]Extraídas!B:B,MATCH(LEFT($A40,6)&"*",[1]Extraídas!A:A,0))="Recibidas", "⏳ Pendiente","❌ No ingresada")), "❌ No ingresada" )} -> ✅ En proceso | C40: {=IFERROR( IF(INDEX([1]PCRs!B:B,MATCH(LEFT($A40,6)&"*",[1]PCRs!A:A,0))="Positivo", "✅ Positivo", IF(INDEX([1]PCRs!B:B,MATCH(LEFT($A40,6)&"*",[1]PCRs!A:A,0))="Negativo", "❌ Negativo", "⏳ No realizado")), "⏳ No realizado" )} -> ⏳ No realizado | D40: =IFERROR( CHOOSE( MATCH(VLOOKUP(LEFT(A87,6)&"*",'Identificación genética'!A:C,2,FALSE), {"En proceso";"Finalizado"},0), "🔬 En proceso", "🎯 Finalizado" ), "❌ NA") -> ❌ NA | E40: CALYPSO | F40: 45947 | G40: =_xlfn.XLOOKUP(A40, Extraídas!A:A, Extraídas!G:G, "") -> ambiental
A41: Agüimes 2 | B41: {=IFERROR( IF(INDEX([1]Extraídas!B:B,MATCH(LEFT($A41,6)&"*",[1]Extraídas!A:A,0))="Extraídas", "✅ En proceso", IF(INDEX([1]Extraídas!B:B,MATCH(LEFT($A41,6)&"*",[1]Extraídas!A:A,0))="Recibidas", "⏳ Pendiente","❌ No ingresada")), "❌ No ingresada" )} -> ✅ En proceso | C41: {=IFERROR( IF(INDEX([1]PCRs!B:B,MATCH(LEFT($A41,6)&"*",[1]PCRs!A:A,0))="Positivo", "✅ Positivo", IF(INDEX([1]PCRs!B:B,MATCH(LEFT($A41,6)&"*",[1]PCRs!A:A,0))="Negativo", "❌ Negativo", "⏳ No realizado")), "⏳ No realizado" )} -> ⏳ No realizado | D41: =IFERROR( CHOOSE( MATCH(VLOOKUP(LEFT(A88,6)&"*",'Identificación genética'!A:C,2,FALSE), {"En proceso";"Finalizado"},0), "🔬 En proceso", "🎯 Finalizado" ), "❌ NA") -> ❌ NA | E41: CALYPSO | F41: 45947 | G41: =_xlfn.XLOOKUP(A41, Extraídas!A:A, Extraídas!G:G, "") -> ambiental
A42: Agüimes 3 | B42: {=IFERROR( IF(INDEX([1]Extraídas!B:B,MATCH(LEFT($A42,6)&"*",[1]Extraídas!A:A,0))="Extraídas", "✅ En proceso", IF(INDEX([1]Extraídas!B:B,MATCH(LEFT($A42,6)&"*",[1]Extraídas!A:A,0))="Recibidas", "⏳ Pendiente","❌ No ingresada")), "❌ No ingresada" )} -> ✅ En proceso | C42: {=IFERROR( IF(INDEX([1]PCRs!B:B,MATCH(LEFT($A42,6)&"*",[1]PCRs!A:A,0))="Positivo", "✅ Positivo", IF(INDEX([1]PCRs!B:B,MATCH(LEFT($A42,6)&"*",[1]PCRs!A:A,0))="Negativo", "❌ Negativo", "⏳ No realizado")), "⏳ No realizado" )} -> ⏳ No realizado | D42: =IFERROR( CHOOSE( MATCH(VLOOKUP(LEFT(A89,6)&"*",'Identificación genética'!A:C,2,FALSE), {"En proceso";"Finalizado"},0), "🔬 En proceso", "🎯 Finalizado" ), "❌ NA") -> ❌ NA | E42: CALYPSO | F42: 45947 | G42: =_xlfn.XLOOKUP(A42, Extraídas!A:A, Extraídas!G:G, "") -> ambiental
A43: AH1A10_EUKB | B43: =IFERROR( IF(INDEX(Extraídas!B:B,MATCH(LEFT($A43,6)&"*",Extraídas!A:A,0))="Extraídas", "✅ En proceso", IF(INDEX(Extraídas!B:B,MATCH(LEFT($A43,6)&"*",Extraídas!A:A,0))="Recibidas", "⏳ Pendiente","❌ No ingresada")), "❌ No ingresada" ) -> ✅ En proceso | C43: {=IFERROR( IF(INDEX([1]PCRs!B:B,MATCH(LEFT($A43,6)&"*",[1]PCRs!A:A,0))="Positivo", "✅ Positivo", IF(INDEX([1]PCRs!B:B,MATCH(LEFT($A43,6)&"*",[1]PCRs!A:A,0))="Negativo", "❌ Negativo", "⏳ No realizado")), "⏳ No realizado" )} -> ✅ Positivo | D43: =IFERROR( CHOOSE( MATCH(VLOOKUP(LEFT(A90,6)&"*",'Identificación genética'!A:C,2,FALSE), {"En proceso";"Finalizado"},0), "🔬 En proceso", "🎯 Finalizado" ), "❌ NA") -> ❌ NA | E43: CALYPSO | F43: 45756 | G43: =_xlfn.XLOOKUP(A43, Extraídas!A:A, Extraídas!G:G, "") -> Microalgas
A44: AH1H12_EUKA | B44: =IFERROR( IF(INDEX(Extraídas!B:B,MATCH(LEFT($A44,6)&"*",Extraídas!A:A,0))="Extraídas", "✅ En proceso", IF(INDEX(Extraídas!B:B,MATCH(LEFT($A44,6)&"*",Extraídas!A:A,0))="Recibidas", "⏳ Pendiente","❌ No ingresada")), "❌ No ingresada" ) -> ✅ En proceso | C44: {=IFERROR( IF(INDEX([1]PCRs!B:B,MATCH(LEFT($A44,6)&"*",[1]PCRs!A:A,0))="Positivo", "✅ Positivo", IF(INDEX([1]PCRs!B:B,MATCH(LEFT($A44,6)&"*",[1]PCRs!A:A,0))="Negativo", "❌ Negativo", "⏳ No realizado")), "⏳ No realizado" )} -> ✅ Positivo | D44: =IFERROR( CHOOSE( MATCH(VLOOKUP(LEFT(A91,6)&"*",'Identificación genética'!A:C,2,FALSE), {"En proceso";"Finalizado"},0), "🔬 En proceso", "🎯 Finalizado" ), "❌ NA") -> ❌ NA | E44: CALYPSO | F44: 45756 | G44: =_xlfn.XLOOKUP(A44, Extraídas!A:A, Extraídas!G:G, "") -> Microalgas
A45: AL1_DS | B45: {=IFERROR( IF(INDEX([1]Extraídas!B:B,MATCH(LEFT($A45,6)&"*",[1]Extraídas!A:A,0))="Extraídas", "✅ En proceso", IF(INDEX([1]Extraídas!B:B,MATCH(LEFT($A45,6)&"*",[1]Extraídas!A:A,0))="Recibidas", "⏳ Pendiente","❌ No ingresada")), "❌ No ingresada" )} -> ✅ En proceso | C45: {=IFERROR( IF(INDEX([1]PCRs!B:B,MATCH(LEFT($A45,6)&"*",[1]PCRs!A:A,0))="Positivo", "✅ Positivo", IF(INDEX([1]PCRs!B:B,MATCH(LEFT($A45,6)&"*",[1]PCRs!A:A,0))="Negativo", "❌ Negativo", "⏳ No realizado")), "⏳ No realizado" )} -> ⏳ No realizado | D45: =IFERROR( CHOOSE( MATCH(VLOOKUP(LEFT(A92,6)&"*",'Identificación genética'!A:C,2,FALSE), {"En proceso";"Finalizado"},0), "🔬 En proceso", "🎯 Finalizado" ), "❌ NA") -> ❌ NA | E45: CALYPSO | F45: 45756 | G45: =_xlfn.XLOOKUP(A45, Extraídas!A:A, Extraídas!G:G, "") -> Macroalgas
A46: AL1_EUKA | B46: =IFERROR( IF(INDEX(Extraídas!B:B,MATCH(LEFT($A46,6)&"*",Extraídas!A:A,0))="Extraídas", "✅ En proceso", IF(INDEX(Extraídas!B:B,MATCH(LEFT($A46,6)&"*",Extraídas!A:A,0))="Recibidas", "⏳ Pendiente","❌ No ingresada")), "❌ No ingresada" ) -> ✅ En proceso | C46: {=IFERROR( IF(INDEX([1]PCRs!B:B,MATCH(LEFT($A46,6)&"*",[1]PCRs!A:A,0))="Positivo", "✅ Positivo", IF(INDEX([1]PCRs!B:B,MATCH(LEFT($A46,6)&"*",[1]PCRs!A:A,0))="Negativo", "❌ Negativo", "⏳ No realizado")), "⏳ No realizado" )} -> ✅ Positivo | D46: =IFERROR( CHOOSE( MATCH(VLOOKUP(LEFT(A93,6)&"*",'Identificación genética'!A:C,2,FALSE), {"En proceso";"Finalizado"},0), "🔬 En proceso", "🎯 Finalizado" ), "❌ NA") -> ❌ NA | E46: CALYPSO | F46: 45756 | G46: =_xlfn.XLOOKUP(A46, Extraídas!A:A, Extraídas!G:G, "") -> Macroalgas
...

Sheet Extraídas
A1: Codigo | B1: Estado | C1: Recibida | D1: Extraída | E1: Organismo | F1: Proyecto | G1: Clase | H1: Protocolo | I1: Elucion_(uL) | J1: DNA_(ng/uL) | K1: DNA 260/280 | L1: DNA 260/230 | M1: Volumen uL PCR A partir de nov | N1: Observaciones
A2: 1 Tif DNAa 16S 1/3 | B2: EXTRAÍDAS | D2: 45947 | E2: Por determinar | F2: CALYPSO-biocrust | G2: ambiental | H2: PROTOCOLO OCTUBRE 2025 | I2: 50 | J2: 16.7 | K2: 1.51 | L2: 0.5 | M2: 0.33
A3: 1 Tif DNAa 16S 2/3 | B3: EXTRAÍDAS | D3: 45947 | E3: Por determinar | F3: CALYPSO-biocrust | G3: ambiental | H3: PROTOCOLO OCTUBRE 2025 | I3: 50 | J3: 13.1 | K3: 1.59 | L3: 0.56 | M3: 0.26
A4: 1 Tif DNAa 16S 3/3 | B4: EXTRAÍDAS | D4: 45947 | E4: Por determinar | F4: CALYPSO-biocrust | G4: ambiental | H4: PROTOCOLO OCTUBRE 2025 | I4: 50 | J4: 6.4 | K4: 1.37 | L4: 0.49 | M4: 0.13
A5: 1.1_MARZO_ALGASAL | B5: Extraídas | D5: 45756 | E5: Eucariota | F5: ALGASAL | G5: Macroalgas | H5: PROTOCOLO MAYO 2025 | I5: 50 | J5: =(11.5582467974799+13.3)/2 -> 12.429123 | K5: 1.9194325 | L5: 1.7755944 | M5: =IF(E5="Procariota", IF(J5<=10,3, IF(J5<=30,2, IF(J5<=100,1, IF(J5<=200,"1:10", IF(J5<=400,"1:20","Fuera de rango") ) ) ) ), IF(E5="Eucariota", IF(J5<=20,3, IF(J5<=60,2, IF(J5<=120,1, IF(J5<=200,"1:10", IF(J5>200,"1:20","Fuera de rango") ) ) ) ), "Error: Tipo inválido") ) -> 3
A6: 1.1RP7 | B6: Extraídas | D6: 45922 | E6: Eucariota | F6: ALGASAL | G6: Macroalgas | H6: PROTOCOLO MAYO 2025 | I6: 50 | J6: 58.9 | K6: 1.91 | L6: 1.26 | M6: =IF(E6="Procariota", IF(J6<=10,3, IF(J6<=30,2, IF(J6<=100,1, IF(J6<=200,"1:10", IF(J6<=400,"1:20","Fuera de rango") ) ) ) ), IF(E6="Eucariota", IF(J6<=20,3, IF(J6<=60,2, IF(J6<=120,1, IF(J6<=200,"1:10", IF(J6>200,"1:20","Fuera de rango") ) ) ) ), "Error: Tipo inválido") ) -> 2
A7: 1.2_MARZO_ALGASAL | B7: Extraídas | D7: 45756 | E7: Eucariota | F7: ALGASAL | G7: Macroalgas | H7: PROTOCOLO MAYO 2025 | I7: 50 | J7: 82.806102 | K7: 2.0541252 | L7: 2.2283732 | M7: =IF(E7="Procariota", IF(J7<=10,3, IF(J7<=30,2, IF(J7<=100,1, IF(J7<=200,"1:10", IF(J7<=400,"1:20","Fuera de rango") ) ) ) ), IF(E7="Eucariota", IF(J7<=20,3, IF(J7<=60,2, IF(J7<=120,1, IF(J7<=200,"1:10", IF(J7>200,"1:20","Fuera de rango") ) ) ) ), "Error: Tipo inválido") ) -> 1
A8: 1.3_MARZO_ALGASAL | B8: Extraídas | D8: 45756 | E8: Eucariota | F8: ALGASAL | G8: Macroalgas | H8: PROTOCOLO MAYO 2025 | I8: 50 | J8: 3.9049377 | K8: 3.2059486 | L8: 0.85636544 | M8: =IF(E8="Procariota", IF(J8<=10,3, IF(J8<=30,2, IF(J8<=100,1, IF(J8<=200,"1:10", IF(J8<=400,"1:20","Fuera de rango") ) ) ) ), IF(E8="Eucariota", IF(J8<=20,3, IF(J8<=60,2, IF(J8<=120,1, IF(J8<=200,"1:10", IF(J8>200,"1:20","Fuera de rango") ) ) ) ), "Error: Tipo inválido") ) -> 3
A9: 2 Tif DNAa 16S 1/3 | B9: EXTRAÍDAS | D9: 45947 | E9: Por determinar | F9: CALYPSO-biocrust | G9: ambiental | H9: PROTOCOLO OCTUBRE 2025 | I9: 50 | J9: 0.66 | K9: 1.63 | L9: 137.9 | M9: 2.76
A10: 2 Tif DNAa 16S 2/3 | B10: EXTRAÍDAS | D10: 45947 | E10: Por determinar | F10: CALYPSO-biocrust | G10: ambiental | H10: PROTOCOLO OCTUBRE 2025 | I10: 50 | J10: 0.75 | K10: 1.59 | L10: 18.6 | M10: 0.37
A11: 2 Tif DNAa 16S 3/3 | B11: EXTRAÍDAS | D11: 45947 | E11: Por determinar | F11: CALYPSO-biocrust | G11: ambiental | H11: PROTOCOLO OCTUBRE 2025 | I11: 50 | J11: 0.58 | K11: 1.65 | L11: 13.1 | M11: 0.26
A12: 2.1 RP9 | B12: EXTRAÍDAS | D12: 45946 | E12: Por determinar | F12: Algasal | G12: MACROALGAS | H12: PROTOCOLO OCTUBRE 2025 | I12: 100 | J12: 0.93 | K12: 1.31 | L12: 6 | M12: 0.06
A13: 2.1_MARZO_ALGASAL | B13: Extraídas | D13: 45756 | E13: Eucariota | F13: ALGASAL | G13: Macroalgas | H13: PROTOCOLO MAYO 2025 | I13: 50 | J13: 187.95426 | K13: 1.8993802 | L13: 1.8861313 | M13: =IF(E13="Procariota", IF(J13<=10,3, IF(J13<=30,2, IF(J13<=100,1, IF(J13<=200,"1:10", IF(J13<=400,"1:20","Fuera de rango") ) ) ) ), IF(E13="Eucariota", IF(J13<=20,3, IF(J13<=60,2, IF(J13<=120,1, IF(J13<=200,"1:10", IF(J13>200,"1:20","Fuera de rango") ) ) ) ), "Error: Tipo inválido") ) -> 1:10
A14: 2.2 RP9 | B14: EXTRAÍDAS | D14: 45946 | E14: Por determinar | F14: Algasal | G14: MACROALGAS | H14: PROTOCOLO OCTUBRE 2025 | I14: 100 | J14: 0.91 | K14: 1.92 | L14: 16.4 | M14: 0.16
A15: 2.2_MARZO_ALGASAL | B15: Extraídas | D15: 45756 | E15: Eucariota | F15: ALGASAL | G15: Macroalgas | H15: PROTOCOLO MAYO 2025 | I15: 50 | J15: 2.8391351 | K15: 1.4034529 | L15: 2.215629 | M15: =IF(E15="Procariota", IF(J15<=10,3, IF(J15<=30,2, IF(J15<=100,1, IF(J15<=200,"1:10", IF(J15<=400,"1:20","Fuera de rango") ) ) ) ), IF(E15="Eucariota", IF(J15<=20,3, IF(J15<=60,2, IF(J15<=120,1, IF(J15<=200,"1:10", IF(J15>200,"1:20","Fuera de rango") ) ) ) ), "Error: Tipo inválido") ) -> 3
A16: 2.2RP7 | B16: Extraídas | D16: 45922 | E16: Eucariota | F16: ALGASAL | G16: Macroalgas | H16: PROTOCOLO MAYO 2025 | I16: 50 | J16: =(183.8+127.9)/2 -> 155.85 | K16: 2 | L16: 1.51 | M16: =IF(E16="Procariota", IF(J16<=10,3, IF(J16<=30,2, IF(J16<=100,1, IF(J16<=200,"1:10", IF(J16<=400,"1:20","Fuera de rango") ) ) ) ), IF(E16="Eucariota", IF(J16<=20,3, IF(J16<=60,2, IF(J16<=120,1, IF(J16<=200,"1:10", IF(J16>200,"1:20","Fuera de rango") ) ) ) ), "Error: Tipo inválido") ) -> 1:10
A17: 2.3 RP9 | B17: EXTRAÍDAS | D17: 45946 | E17: Por determinar | F17: Algasal | G17: MACROALGAS | H17: PROTOCOLO OCTUBRE 2025 | I17: 200 | J17: 1.06 | K17: 1.92 | L17: 253.4 | M17: 1.27
A18: 2.3_MARZO_ALGASAL | B18: Extraídas | D18: 45756 | E18: Eucariota | F18: ALGASAL | G18: Macroalgas | H18: PROTOCOLO MAYO 2025 | I18: 50 | J18: 4.1322533 | K18: 1.94634 | L18: 3.09 | M18: =IF(E18="Procariota", IF(J18<=10,3, IF(J18<=30,2, IF(J18<=100,1, IF(J18<=200,"1:10", IF(J18<=400,"1:20","Fuera de rango") ) ) ) ), IF(E18="Eucariota", IF(J18<=20,3, IF(J18<=60,2, IF(J18<=120,1, IF(J18<=200,"1:10", IF(J18>200,"1:20","Fuera de rango") ) ) ) ), "Error: Tipo inválido") ) -> 3
A19: 2.3RP7 | B19: Extraídas | D19: 45922 | E19: Eucariota | F19: ALGASAL | G19: Macroalgas | H19: PROTOCOLO MAYO 2025 | I19: 50 | J19: 117.3 | K19: 1.45 | L19: 2.0593004 | M19: =IF(E19="Procariota", IF(J19<=10,3, IF(J19<=30,2, IF(J19<=100,1, IF(J19<=200,"1:10", IF(J19<=400,"1:20","Fuera de rango") ) ) ) ), IF(E19="Eucariota", IF(J19<=20,3, IF(J19<=60,2, IF(J19<=120,1, IF(J19<=200,"1:10", IF(J19>200,"1:20","Fuera de rango") ) ) ) ), "Error: Tipo inválido") ) -> 1
A20: 2.4 RP9 | B20: EXTRAÍDAS | D20: 45946 | E20: Por determinar | F20: Algasal | G20: MACROALGAS | H20: PROTOCOLO OCTUBRE 2025 | I20: 200 | J20: 1.49 | K20: 2.02 | L20: 159.8 | M20: 0.8
A21: 2.4RP7 | B21: Extraídas | D21: 45922 | E21: Eucariota | F21: ALGASAL | G21: Macroalgas | H21: PROTOCOLO MAYO 2025 | I21: 50 | J21: 24.6 | K21: 1.48 | L21: 0.29 | M21: =IF(E21="Procariota", IF(J21<=10,3, IF(J21<=30,2, IF(J21<=100,1, IF(J21<=200,"1:10", IF(J21<=400,"1:20","Fuera de rango") ) ) ) ), IF(E21="Eucariota", IF(J21<=20,3, IF(J21<=60,2, IF(J21<=120,1, IF(J21<=200,"1:10", IF(J21>200,"1:20","Fuera de rango") ) ) ) ), "Error: Tipo inválido") ) -> 2
A22: 2.5RP7 | B22: Extraídas | D22: 45922 | E22: Eucariota | F22: ALGASAL | G22: Macroalgas | H22: PROTOCOLO MAYO 2025 | I22: 50 | J22: 54.3 | K22: 1.8 | L22: 0.76 | M22: =IF(E22="Procariota", IF(J22<=10,3, IF(J22<=30,2, IF(J22<=100,1, IF(J22<=200,"1:10", IF(J22<=400,"1:20","Fuera de rango") ) ) ) ), IF(E22="Eucariota", IF(J22<=20,3, IF(J22<=60,2, IF(J22<=120,1, IF(J22<=200,"1:10", IF(J22>200,"1:20","Fuera de rango") ) ) ) ), "Error: Tipo inválido") ) -> 2
A23: 3.1 RP9 | B23: EXTRAÍDAS | D23: 45946 | E23: Por determinar | F23: Algasal | G23: MACROALGAS | H23: PROTOCOLO OCTUBRE 2025 | I23: 200 | J23: 1.19 | K23: 1.96 | L23: 269.9 | M23: 1.35
A24: 3.1_MARZO_ALGASAL | B24: Extraídas | D24: 45756 | E24: Eucariota | F24: ALGASAL | G24: Macroalgas | H24: PROTOCOLO MAYO 2025 | I24: 50 | J24: 15.955773 | K24: 1.4521331 | L24: 0.80196457 | M24: =IF(E24="Procariota", IF(J24<=10,3, IF(J24<=30,2, IF(J24<=100,1, IF(J24<=200,"1:10", IF(J24<=400,"1:20","Fuera de rango") ) ) ) ), IF(E24="Eucariota", IF(J24<=20,3, IF(J24<=60,2, IF(J24<=120,1, IF(J24<=200,"1:10", IF(J24>200,"1:20","Fuera de rango") ) ) ) ), "Error: Tipo inválido") ) -> 3
A25: 3.2 RP9 | B25: EXTRAÍDAS | D25: 45946 | E25: Por determinar | F25: Algasal | G25: MACROALGAS | H25: PROTOCOLO OCTUBRE 2025 | I25: 200 | J25: 0.69 | K25: 1.83 | L25: 242.7 | M25: 1.21
A26: 3.2_MARZO_ALGASAL | B26: Extraídas | D26: 45756 | E26: Eucariota | F26: ALGASAL | G26: Macroalgas | H26: PROTOCOLO MAYO 2025 | I26: 50 | J26: 68.314876 | K26: 2.0435051 | L26: 1.7536485 | M26: =IF(E26="Procariota", IF(J26<=10,3, IF(J26<=30,2, IF(J26<=100,1, IF(J26<=200,"1:10", IF(J26<=400,"1:20","Fuera de rango") ) ) ) ), IF(E26="Eucariota", IF(J26<=20,3, IF(J26<=60,2, IF(J26<=120,1, IF(J26<=200,"1:10", IF(J26>200,"1:20","Fuera de rango") ) ) ) ), "Error: Tipo inválido") ) -> 1 | R26: 5
A27: 3.2RP7 | B27: Extraídas | D27: 45922 | E27: Eucariota | F27: ALGASAL | G27: Macroalgas | H27: PROTOCOLO MAYO 2025 | I27: 50 | J27: 349.2 | K27: 2.03 | L27: 1.96 | M27: =IF(E27="Procariota", IF(J27<=10,3, IF(J27<=30,2, IF(J27<=100,1, IF(J27<=200,"1:10", IF(J27<=400,"1:20","Fuera de rango") ) ) ) ), IF(E27="Eucariota", IF(J27<=20,3, IF(J27<=60,2, IF(J27<=120,1, IF(J27<=200,"1:10", IF(J27>200,"1:20","Fuera de rango") ) ) ) ), "Error: Tipo inválido") ) -> 1:20
A28: 3.3 RP9 | B28: EXTRAÍDAS | D28: 45946 | E28: Por determinar | F28: Algasal | G28: MACROALGAS | H28: PROTOCOLO OCTUBRE 2025 | I28: 200 | J28: 0.98 | K28: 1.9 | L28: 175.2 | M28: 0.88 | R28: 5
A29: 3.4 RP9 | B29: EXTRAÍDAS | D29: 45946 | E29: Por determinar | F29: Algasal | G29: MACROALGAS | H29: PROTOCOLO OCTUBRE 2025 | I29: 200 | J29: 1.72 | K29: 1.9 | L29: 125.1 | M29: 0.63 | R29: 5
A30: 3.5 RP9 | B30: EXTRAÍDAS | D30: 45946 | E30: Por determinar | F30: Algasal | G30: MACROALGAS | H30: PROTOCOLO OCTUBRE 2025 | I30: 200 | J30: 1.13 | K30: 1.93 | L30: 206.4 | M30: 1.03
A31: 3.6 RP9 | B31: EXTRAÍDAS | D31: 45946 | E31: Por determinar | F31: Algasal | G31: MACROALGAS | H31: PROTOCOLO OCTUBRE 2025 | I31: 200 | J31: 1.63 | K31: 2.03 | L31: 346.1 | M31: 1.73
A32: 3.6RP7 | B32: Extraídas | D32: 45922 | E32: Eucariota | F32: ALGASAL | G32: Macroalgas | H32: PROTOCOLO MAYO 2025 | I32: 50 | J32: 0.64 | K32: 1.61 | L32: 89.4 | M32: =IF(E32="Procariota", IF(L32<=10,3, IF(L32<=30,2, IF(L32<=100,1, IF(L32<=200,"1:10", IF(L32<=400,"1:20","Fuera de rango") ) ) ) ), IF(E32="Eucariota", IF(L32<=20,3, IF(L32<=60,2, IF(L32<=120,1, IF(L32<=200,"1:10", IF(L32>200,"1:20","Fuera de rango") ) ) ) ), "Error: Tipo inválido") ) -> 1
A33: A1.1_EUKA | B33: Extraídas | D33: 45756 | E33: Eucariota | F33: ALGASAL | G33: Macroalgas | H33: PROTOCOLO MAYO 2025 | I33: 50 | J33: =(11.5582467974799+13.3)/2 -> 12.429123 | K33: 1.9194325 | L33: 1.7755944 | M33: =IF(E33="Procariota", IF(J33<=10,3, IF(J33<=30,2, IF(J33<=100,1, IF(J33<=200,"1:10", IF(J33<=400,"1:20","Fuera de rango") ) ) ) ), IF(E33="Eucariota", IF(J33<=20,3, IF(J33<=60,2, IF(J33<=120,1, IF(J33<=200,"1:10", IF(J33>200,"1:20","Fuera de rango") ) ) ) ), "Error: Tipo inválido") ) -> 3
A34: A1.2_EUKA | B34: Extraídas | D34: 45756 | E34: Eucariota | F34: ALGASAL | G34: Macroalgas | H34: PROTOCOLO MAYO 2025 | I34: 50 | J34: 82.806102 | K34: 2.0541252 | L34: 2.2283732 | M34: =IF(E34="Procariota", IF(J34<=10, 3, IF(J34<=50, 2, IF(J34<=100, 2, IF(J34<=200, 2, 2)))), IF(E34="eucariotas", IF(J34<=10, 3, IF(J34<=50, 2, IF(J34<=100, 2, IF(J34<=200, 1, 1)))), "Error: Tipo inválido")) -> Error: Tipo inválido
A35: A1.3_EUKA | B35: Extraídas | D35: 45756 | E35: Eucariota | F35: ALGASAL | G35: Macroalgas | H35: PROTOCOLO MAYO 2025 | I35: 50 | J35: 3.9049377 | K35: 3.2059486 | L35: 0.85636544 | M35: =IF(E35="Procariota", IF(J35<=10, 3, IF(J35<=50, 2, IF(J35<=100, 2, IF(J35<=200, 2, 2)))), IF(E35="eucariotas", IF(J35<=10, 3, IF(J35<=50, 2, IF(J35<=100, 2, IF(J35<=200, 1, 1)))), "Error: Tipo inválido")) -> Error: Tipo inválido
A36: A2.1_EUKA | B36: Extraídas | D36: 45756 | E36: Eucariota | F36: ALGASAL | G36: Macroalgas | H36: PROTOCOLO MAYO 2025 | I36: 50 | J36: 187.95426 | K36: 1.8993802 | L36: 1.8861313 | M36: =IF(E36="Procariota", IF(J36<=10, 3, IF(J36<=50, 2, IF(J36<=100, 2, IF(J36<=200, 2, 2)))), IF(E36="eucariotas", IF(J36<=10, 3, IF(J36<=50, 2, IF(J36<=100, 2, IF(J36<=200, 1, 1)))), "Error: Tipo inválido")) -> Error: Tipo inválido
A37: A2.2_EUKA | B37: Extraídas | D37: 45756 | E37: Eucariota | F37: ALGASAL | G37: Macroalgas | H37: PROTOCOLO MAYO 2025 | I37: 50 | J37: 2.8391351 | L37: 2.215629 | M37: =IF(E37="Procariota", IF(J37<=10, 3, IF(J37<=50, 2, IF(J37<=100, 2, IF(J37<=200, 2, 2)))), IF(E37="eucariotas", IF(J37<=10, 3, IF(J37<=50, 2, IF(J37<=100, 2, IF(J37<=200, 1, 1)))), "Error: Tipo inválido")) -> Error: Tipo inválido
A38: A3.1_EUKA | B38: Extraídas | D38: 45756 | E38: Eucariota | F38: ALGASAL | G38: Macroalgas | H38: PROTOCOLO MAYO 2025 | I38: 50 | J38: 4.1322533 | K38: 1.94634 | L38: 2.0593004
A39: A3.2_EUKA | B39: Extraídas | D39: 45756 | E39: Eucariota | F39: ALGASAL | G39: Macroalgas | H39: PROTOCOLO MAYO 2025 | I39: 50 | J39: 15.955773 | K39: 1.4521331 | L39: 0.80196457
A40: Agüimes 1 | B40: EXTRAÍDAS | D40: 45947 | E40: Por determinar | F40: CALYPSO-biocrust | G40: ambiental | H40: PROTOCOLO OCTUBRE 2025 | I40: 100 | J40: 0.52 | K40: 1.5 | L40: 9.8 | M40: 0.1
...

Sheet PCRs
A1: Codigo | B1: Resultado | C1: Proyecto | D1: Primer | E1: PCR | F1: Fecha_PCR | G1: FechaPCRREPETIDA | H1: Observaciones | I1: PLACA | J1: FechaenvíoPlaca
A2: 1.1 | B2: NEGATIVO | C2: Sanger_ALGASAL | D2: ITS1/ITS4 | E2: 16 | F2: 45833 | G2: - | H2: SECUENCIADA | I2: - | J2: -
A3: 1.1MARZOALGASAL | B3: NEGATIVO | C3: Sanger_ALGASAL | D3: TufA4/R | E3: 24 | F3: 45951 | H3: SECUENCIADA
A4: 1.1MARZOALGASAL | B4: NEGATIVO | C4: Sanger_ALGASAL | D4: SSU/ITS4 | E4: 25 | F4: 45953 | H4: SECUENCIADA
A5: 1.1 | B5: POSITIVO | C5: Sanger_ALGASAL | D5: rbcLaF/LaR | E5: 17 | F5: 45833 | G5: 45905 | H5: ACEPTADO | I5: 2 | J5: 45910
A6: 1.1MARZO | B6: NEGATIVO | C6: Sanger_ALGASAL | D6: SSU/ITS4 | E6: 27 | F6: 45958 | H6: SECUENCIADA
A7: 1.1x2 | B7: NEGATIVO | C7: Sanger_ALGASAL | D7: rbcLaF/LaR | E7: 17 | F7: 45833 | G7: - | H7: SECUENCIADA | I7: - | J7: -
A8: 1.1x2 | B8: POSITIVO | C8: Sanger_ALGASAL | D8: TufA4/R | E8: 24 | F8: 45951 | H8: ACEPTADO | I8: 5
A9: 1.21 | B9: POSITIVO | C9: Sanger_ALGASAL | D9: ITS1/ITS4 | E9: 16 | F9: 45833 | G9: 45905 | H9: ACEPTADO | I9: 2 | J9: 45910
A10: 1.2 | B10: POSITIVO | C10: Sanger_ALGASAL | D10: rbcLaF/LaR | E10: 17 | F10: 45833 | G10: 45905 | H10: ACEPTADO | I10: 2 | J10: 45910
A11: 1.3 | B11: NEGATIVO | C11: Sanger_ALGASAL | D11: ITS1/ITS4 | E11: 16 | F11: 45833 | G11: - | H11: SECUENCIADA | I11: - | J11: -
A12: 1.3MARZOALGASAL | B12: NEGATIVO | C12: Sanger_ALGASAL | D12: SSU/ITS4 | E12: 25 | F12: 45953 | H12: SECUENCIADA
A13: 1.3MARZO | B13: POSITIVO | C13: Sanger_ALGASAL | D13: TufA4/R | E13: 24 | F13: 45951 | H13: ACEPTADO | I13: 5
A14: 1.3 | B14: POSITIVO | C14: Sanger_ALGASAL | D14: rbcLaF/LaR | E14: 17 | F14: 45833 | G14: 45905 | H14: ACEPTADO | I14: 2 | J14: 45910
A15: 1.3MARZO | B15: POSITIVO | C15: Sanger_ALGASAL | D15: SSU/ITS4 | E15: 27 | F15: 45958 | H15: ACEPTADO | I15: 5
A16: 2.11 | B16: POSITIVO | C16: Sanger_ALGASAL | D16: ITS1/ITS4 | E16: 16 | F16: 45833 | G16: 45905 | H16: ACEPTADO | I16: 2 | J16: 45910
A17: 2.1 | B17: POSITIVO | C17: Sanger_ALGASAL | D17: rbcLaF/LaR | E17: 17 | F17: 45833 | G17: 45905 | H17: ACEPTADO | I17: 2 | J17: 45910
A18: 2.2 | B18: NEGATIVO | C18: Sanger_ALGASAL | D18: ITS1/ITS4 | E18: 16 | F18: 45833 | G18: - | H18: SECUENCIADA | I18: - | J18: -
A19: 2.2MARZOALGASAL | B19: NEGATIVO | C19: Sanger_ALGASAL | D19: TufA4/R | E19: 24 | F19: 45951 | H19: SECUENCIADA
A20: 2.2MARZOALGASAL | B20: NEGATIVO | C20: Sanger_ALGASAL | D20: SSU/ITS4 | E20: 25 | F20: 45953 | H20: SECUENCIADA
A21: 2.2 | B21: NEGATIVO | C21: Sanger_ALGASAL | D21: rbcLaF/LaR | E21: 17 | F21: 45833 | G21: - | H21: SECUENCIADA | I21: - | J21: -
A22: 2.2MARZO | B22: NEGATIVO | C22: Sanger_ALGASAL | D22: SSU/ITS4 | E22: 27 | F22: 45958 | H22: SECUENCIADA
A23: 2.3 | B23: NEGATIVO | C23: Sanger_ALGASAL | D23: ITS1/ITS4 | E23: 16 | F23: 45833 | G23: - | H23: SECUENCIADA | I23: - | J23: -
A24: 2.3MARZOALGASAL | B24: NEGATIVO | C24: Sanger_ALGASAL | D24: TufA4/R | E24: 24 | F24: 45951 | H24: SECUENCIADA
A25: 2.3MARZOALGASAL | B25: NEGATIVO | C25: Sanger_ALGASAL | D25: SSU/ITS4 | E25: 25 | F25: 45953 | H25: SECUENCIADA
A26: 2.3 | B26: NEGATIVO | C26: Sanger_ALGASAL | D26: rbcLaF/LaR | E26: 17 | F26: 45833 | G26: - | H26: SECUENCIADA | I26: - | J26: -
A27: 2.3MARZO | B27: NEGATIVO | C27: Sanger_ALGASAL | D27: SSU/ITS4 | E27: 27 | F27: 45958 | H27: SECUENCIADA
A28: 3.1 | B28: NEGATIVO | C28: Sanger_ALGASAL | D28: ITS1/ITS4 | E28: 16 | F28: 45833 | G28: - | H28: SECUENCIADA | I28: - | J28: -
A29: 3.1MARZOALGASAL | B29: NEGATIVO | C29: Sanger_ALGASAL | D29: TufA4/R | E29: 24 | F29: 45951 | H29: SECUENCIADA
A30: 3.1MARZOALGASAL | B30: NEGATIVO | C30: Sanger_ALGASAL | D30: SSU/ITS4 | E30: 25 | F30: 45953 | H30: SECUENCIADA
A31: 3.1MARZO | B31: NEGATIVO | C31: Sanger_ALGASAL | D31: SSU/ITS4 | E31: 27 | F31: 45958 | H31: SECUENCIADA
A32: 3.2 | B32: NEGATIVO | C32: Sanger_ALGASAL | D32: ITS1/ITS4 | E32: 16 | F32: 45833 | G32: - | H32: SECUENCIADA | I32: - | J32: -
A33: 3.2 | B33: NEGATIVO | C33: Sanger_ALGASAL | D33: rbcLaF/LaR | E33: 17 | F33: 45833 | G33: - | H33: SECUENCIADA | I33: - | J33: -
A34: A1.1 | B34: POSITIVO | C34: Sanger_ALGASAL | D34: EUKA/EUKB | E34: 1 | F34: 45817 | G34: - | H34: ACEPTADO | I34: 1 | J34: 45824
A35: A1.2 | B35: POSITIVO | C35: Sanger_ALGASAL | D35: EUKA/EUKB | E35: 1 | F35: 45817 | G35: - | H35: ACEPTADO | I35: 1 | J35: 45824
A36: A1.3 | B36: POSITIVO | C36: Sanger_ALGASAL | D36: EUKA/EUKB | E36: 1 | F36: 45817 | G36: - | H36: ACEPTADO | I36: 1 | J36: 45824
A37: A2.1 | B37: POSITIVO | C37: Sanger_ALGASAL | D37: EUKA/EUKB | E37: 1 | F37: 45817 | G37: - | H37: ACEPTADO | I37: 1 | J37: 45824
A38: A2.2 | B38: NEGATIVO | C38: Sanger_ALGASAL | D38: EUKA/EUKB | E38: 1 | F38: 45817 | G38: - | H38: SECUENCIADA | I38: - | J38: -
A39: A2.3 | B39: NEGATIVO | C39: Sanger_ALGASAL | D39: EUKA/EUKB | E39: 1 | F39: 45818 | G39: - | H39: SECUENCIADA | I39: - | J39: -
A40: A3.1 | B40: NEGATIVO | C40: Sanger_ALGASAL | D40: EUKA/EUKB | E40: 1 | F40: 45817 | G40: - | H40: SECUENCIADA | I40: - | J40: -
...

Sheet Identificación genética
A1: Codigo | B1: Estado | C1: Placa | D1: Fecha_Placa | E1: Tipo | F1: PCR | G1: Primer | H1: Fecha_PCR | I1: Calidad secuencia | J1: PRIMER | K1: Resultado | L1: Fecha_análisis_secuencia | M1: Secuencia FASTA | N1: Observaciones
A2: A1.1 | B2: Finalizado | C2: PLACA 1 | D2: 45824 | E2: Sanger-ALGASAL | F2: 1 | G2: EUKA/EUKB | H2: 45817 | I2: BAJA CALIDAD | J2: CONJUNTO | K2: POSITIVO | L2: 45833 | M2: >A1_1_EUKAB_LOWQUALITY TTTGATGGTACCACACTACTCGGATAACCGTATTAAAGCTACAGCTAATACGTGCGCAACTCCCGACTCACGAAGGGACGTATTTATTATATTCAAGACCGACCGTGCTTGCACGTCTTTGGTGAATCATGGAAACTTCACGAATCGCAGGGTTTATCCCGGCGATGTTTCATTCAACTTTCTGCCCTATCAACTTTCGACGGGAGTATACAGGACTACCGTGGTGGTAACGGATGACGGAGGATTAGGGTTCGATTCCGGATAGGGAGCCTGATAAACGGCTACCACATCCAAGGAAGGCAGCAGGCCCGCAAATTACCCAATCCTGACACAGGGAGGTAGTGACAATAAATATCAATTCTGGGCCACATGGTCCGGTAATTGGAATGAGTACAATGTAAACACCTTAACGAGGATCCATTGGAGGGCAAGTCTGGTGCCAGCAGCCGCGGCAATTCCAGCTCCAATAACGTATATTTAAGTTGTTGCAGTTAAAAAGCTCGTACTTGGATTTCGGGTGGGACGCAGCGGTCTCGCATTGCGTTTGTACTGCTGCACCGCCTCCTTCTTGCCGGGGGGCGGCCCATCGGACTTCACTGTCTGGGGCGTCAGAATCGGCGATGTTACTGTGAGTAAATTAGAGTGTTCAAAGCAAGCGTACGCTCTGAATATAATAACATGGGATAACACCACAGGACTCTGGCCTATCTTGTTGGTCTATAAGACCAGAATAATGATTAATAG
A3: A1.2 | B3: Finalizado | C3: PLACA 1 | D3: 45824 | E3: Sanger-ALGASAL | F3: 1 | G3: EUKA/EUKB | H3: 45817 | I3: BUENA CALIDAD | J3: CONJUNTO | K3: POSITIVO | L3: 45833 | M3: >A1_2_EUKB GGCAATTTGGGCCAGCAGCCCGGTATTCCAGTTCCAATAGCGTATATTAAGTTTTGCAGTAAAAGCTCGTAGTGGATTTCGGGTGGACGCAGCGTCTCGCATGCGTTGTACTGCTGCAGCCCTCTTTTTGCCGGGGCGGCCCATCGGACTTCACTGTCTGGGGTCAGAATCGGCGATGTTACTTTGAGTAAATTAGAGTGTTCAAAGCAAGCTTACGCTCTGAATATAATAGCATGGGATAACACGACAGGACTCTGGCCTATCGTGTTGGTCTATAGGACCAGAGTAATGATTAAGAGGGACAGTCGGGGGCATTCGTATTCCGTTGTCAGAGGTGAAATTCTTGGATTTACGGAAGACGAACATCTGCGAAAGCATTTGCCAAGGATGTTTTCATTGATCAAGAACGAAAGTTGGGGGCTCGAAGACGATTAGATACCGTCGTAGTCTCAACCATAAACGATGCCGACTAGGGATTGGCGGGTGTTTTTTTGATGACTCCGCCAGCACCTCATGAGAAATCAAAGTTTTTGGGTTCCGGGGGGAGTATGGTCGCAAGGCTGAAACTTAAAGGAATTGACGGAAGGGCACCACCAGGCGTGGAGCCTGCGGCTTAATTTGACTCAACACGGGAAAACTTACCAGGTCCAGACATAGGAAGGATTGACAGATTGAGAGCTCTTTCTTGATTCTATGGGTGGTGGTGCATGGCCGTTCTTAGTTGGTGGGTTGCCTTGTCAGGTTGATTCCGGTAACGAACGAGACCTCAGCCTGCTAAATAGTGACGTCTGCTTCGGCAGTCGCGCGCTTCTTAGAGGGACTGTTGGCGTCTAGCCAATGGAAGTATGAGGCAATAACAGGTCTGTGATGCCCTTAGATGTTCTGGGCCGCACGCGCGCTACACTGATACGTTCAACGAGCTCCTTGACCGAGAGGTCCGGGTAATCTTTGAAACCGTATCGTGATGGGGATAGAACATTGCAATTATTGTTCTTCAACGAGGAATGCCTAGTAAGCGCGAGTCATCATCTCGCGTTGATTACGTCCCTGCCCTTTGTACACACCGCCCGTCGCTCCTACCGATTGAACGTGCTGGTGAAGCGTTAGGACTGGAACTTTGGGCCGGTCTCCTGCCCATCGTTTCGGGAATTTCGTAGAAC | N3: Filogenia
A4: A1.3 | B4: Finalizado | C4: PLACA 1 | D4: 45824 | E4: Sanger-ALGASAL | F4: 1 | G4: EUKA/EUKB | H4: 45817 | I4: BAJA CALIDAD | J4: CONJUNTO | K4: REPETIDO | L4: 45833 | M4: >A1_3_EUKA_lOQQC_DOBLESEQ CTGACGGCGACTGAGATTACGCCATGCATGTCTAGTATAAACCGTTTATACTGTAGAAACTGCGAAGGGCTCATTAAATCATTTAGATTTTATTTGATGGCCCCACACTACTCGGATAACCGTAATAAAGCTACAGCTAATACGTGCGTAACTCCCGACTTACGAAGGGACGTATTTATTAGATTCCCCCCGACCGTGCTTGCACGTCTTTGGTGAATCATGGGAACTTCACGAATCGCAGGGTCTATCCCGGCGATGTTTCATTCAACTTTCTGCCCTATCAACTTTCGACGGTGGTATAGAGGACTACCGTGGTGGTAACGGGTGACGGAGGATTAGGGTTCAATTCCGGACAGGGAGCCTGATAAACGGCTACCACATCCAAGGAAGGCAGCAAGCGCGCAAATTACCCAATCCTGACGCAGGGAGGTAGTGACAATAAATATCAATTCTGGGCCACTTGGTCCGGTAATTGGAATGATTACAACGCATACGCCTTAACCAGGATCCATTGGAGGGCGAGTCTGGTGCCCGCAGCCGCGGCAATTCCAGCTCCAATAACGTATATTTAAGTTGTTGCAGTTAAAAAACTCGTAGTTGGATTTCGTGTGGGACGCACCGGTCTCCCATTGCTGTTGTACTGCTGCAGCCCTCCTTCTTGCCGGGGGCGGCCCGTCGCACTTCACTGTCTGGGGGTCAGAGTCGGCGATGTTACTTTGAATAAATTAGAGTGTTCAAAGCAAGCTTACGCTCTGAATATAATTAGCAT | N4: Filogenia
A5: A2.1 | B5: Finalizado | C5: PLACA 1 | D5: 45824 | E5: Sanger-ALGASAL | F5: 1 | G5: EUKA/EUKB | H5: 45817 | I5: BUENA CALIDAD | J5: CONJUNTO | K5: POSITIVO | L5: 45833 | M5: >A2_1_EUKAB TGCATGTCTAAGTATAAACAGTTTATACTGTGAAACTGCGAATGGCTCATTAAATCAGTTAGAGTTTATTTGATGGTACCACACTACTCGGATAACCGTAGTAAAGCTACAGCTAATACGTGCGTAACTCCCGACTTACGAAGGGACGTATTTATTAGATTCAAGGCCGACCGTGCTTGCACGTCTTTGGTGAATCATGGTAACTTCACGAATCGCAGGGTTTATCCCGGCGATGTTTCATTCAACTTTCTGCCCTATCAACTTTCGACGGTAGTATAGAGGACTACCGTGGTGGTAACGGGTGACGGAGGATTAGGGTTCGATTCCGGAGAGGGAGCCTGAGAAACGGCTACCACATCCAAGGAAGGCAGCAGGCGCGCAAATTACCCAATCCTGACACAGGGAGGTAGTGACAATAAATATCAATTCTGGGCCACATGGTCCGGTAATTGGAATGAGTACAATGTAAACGCCTTAACGAGGATCCATTGGAGGGCAAGTCTGGTGCCAGCAGCCGCGGTAATTCCAGCTCCAATAGCGTATATTTAAGTTGTTGCAGTTAAAAAGCTCGTAGTTGGATTTCGGGTGGGACGCAGCGGTCTCGCATTGCGTTTGTACTGCTGCAGCCCTCCTTCTTGCCGGGGGCGGCCCATCGGACTTCACTGTCTGGGGGTCAGAATCGGCGATGTTACTTTGAGTAAATTAGAGTGTTCAAAGCAAGCTTACGCTCTGAATATAATAGCATGGGATAACACGACAGGACTCTGGCCTATCGTGTTGGTCTATAGGACCAGAGTAATGATTAAGAGGGACAGTCGGGGGCATTCGTATTCCGTTGTCAGAGGTGAAATTCTTGGATTTACGGAAGACGAACATCTGCGAAAGCATTTGCCAAGGATGTTTTCATTGATCAAGAACGAAAGTTGGGGGCTCGAAGACGATTAGATACCGTCGTAGTCTCAACCATAAACGATGCCGACTAGGGATTGGCGGGTGTTTTTTTGATGACTCCGCCAGCACCTCATGAGAAATCAAAGTTTTTGGGTTCCGGGGGGAGTATGGTCGCAAGGCTGAAACTTAAAGGAATTGACGGAAGGGCACCACCAGGCGTGGAGCCTGCGGCTTAATTTGACTCAACACGGGAAAACTTACCAGGTCCAGACATAGGAAGGATTGACAGATTGAGAGCTCTTTCTTGATTCTATGGGTGGTGGTGCATGGCCGTTCTTAGTTGGTGGGTTGCCTTGTCAGGTTGATTCCGGTAACGAACGAGACCTCAGCCTGCTAAATAGTGACGTCTGCTTCGGCAGTCGCGCGCTTCTTAGAGGGACTGTTGGCGTCTAGCCAATGGAAGTATGAGGCAATAACAGGTCTGTGATGCCCTTAGATGTTCTGGGCCGCACGCGCGCTACACTGATACGTTCAACGAGCTCCTTGACCGAGAGGTCCGGGTAATCTTTGAAACCGTATCGTGATGGGGATAGAACATTGCAATTATTGTTCTTCAACGAGGAATGCCTAGTAAGCGCGAGTCATCATCTCGCGTTGATTACGTCCCTGCCCTTTGTACACACCGCCCGTCGCTCCTACCGATTGAACGTGCTGGTGAAGCGTTAGGACTGGAACTTTGGGCCGGTCTCCTGCCCATTGTTTC | N5: Filogenia
A6: A2.2 | B6: Finalizado | C6: PLACA 1 | D6: 45824 | E6: Sanger-ALGASAL | F6: 1 | G6: EUKA/EUKB | H6: 45817 | I6: BUENA CALIDAD | J6: CONJUNTO | K6: POSITIVO | L6: 45833 | M6: >A2_2_EUKAB TGTAGGTATAACCTGTATACCGGTAAACTGCGAATGGCTCGGTAAATCAGTTATAGTTTATTTGATAGTGCAACCTACTCGGATAACCGTAGTAACACTAGAGCTAATACGTGCGTAAATCCCGACTTTTTGAAGGGACGTATTTATTAGATTTATGGTCAGCCGGGCTTGCCCGACCAGCGGTGAATCATGGTAACTTGACGGATTGCATGGCCTTCGTGCCGGCGACGTGTCATTCAAGTTTCTGCCCCATCAGGTTTCGACTGTAGTGTATTGGACTACAGTGCCTATAACGGGTAGCGGAGGATTAGGGTTCGATTCCGGAGAGGGAGCCTGAGAAACGGCTACCACATCCAAGGAAGGCAGCAGGCGCGCAAATTACCCAATCCCAATTCAGGGAGGTAGTGACAAGAAATAGCAATGCGGGGCGGATTCGCTCTGCAATTGGAATGAGAACAATGTAAACCACTTAACGAGTATCAATTGGAGGGCAAGTCTGGTGCCAGCAGCCGCGGTAATTCCAGCTCCAATAGCGTATATGTAAGTTGTTGCGATTAAAAAGCCCGTAGCTGAACCTCGGGTAACCCTGCCGGTCCGCATCATGTGAGTACTGTCGTGGGTTGCCTTTCTGGTAAGACCGTATCACGGGGTTAATTCACCGGGAACGAGGCTTGCCAAGGTTACTTTGAGTAAAATAGAGTGTTCAAAGCAAGCATGCGCTATGAATACACTAGCATGGGATAACACGACATGACCGGCGGTCTATCTTGTTGGCCTGTAGATCTGTTGGTAATGGCTAATAGGGACGGTCGGGGGCATTCGTATTTCGCTGTCAGAGGTGAAATTCTTGGATTTGCGAAAGACGAACTACTGCGAAAGCATTTGCCAAGGACGCTTTCATTAGTCAAGGACGAAAGTCGGGGGATCGAAGACGATTAGATACCGTCGTAGTCTCGACCATAAACGATGCCAATTAGGGATTGGAGGGCGGATCCATTATGCCTCCTCCAGCACCTTCCGCGAAAGCAAAATTTATGGGCTTCGGGGGGAGTATGGTCGCAGGGCTGAAACTTAAAGGAATTGACGGAACGGCACCACCAGGCGTGGAGCCTGCGGCTTAATTTGACTCAACACGGGAAAACTTACCAGGTCCAGACAAGAGGAGGATTTACAGATTGATAGCTCTTTAAAGATTTTTTGGATGGTGGTGCATGGCCGTTCTTAGTTCGTGGATTGATTTGTCAGGTTGATTCCGGTAACGGACGAGACCCCAACCTACTAACTAGCTCTGGTTGATATACAGCCTGCCAGCTTCTTAGAGGGACTCTCGGAATGAAACCGAAGGAGGTGGGGCAATAACAGGTCTGTGATGCCCTTAGATGTCCTGGGCCGCACGCGCGCTACACTGATGCATTCAACGAGCCTACCTGTGCCGAGAGGTATGGGCAATCTGCGAAACTGCATCGTGATGGGGCTAGATTATTGCAATTATTGATCTTCAACGAGGAATGCCTAGTAAGCGCGAGTCATCAACTCGCGTTGATTACGTCCCTGCCGTTTGTACACACCGCCCGTCGCTCCTACCGATTGAGTGTGCTGGTGAAATGTTCGGATTGGACGGCCGTTCGTAAGAGGGTCTTCTGAGAAGTTCATTGAACCCTCTCACTAGAGAATGAGAGCTGTATGCCTAC | N6: Filogenia
A7: A3.1 | B7: Finalizado | C7: PLACA 1 | D7: 45824 | E7: Sanger-ALGASAL | F7: 1 | G7: EUKA/EUKB | H7: 45817 | I7: BUENA CALIDAD | J7: CONJUNTO | K7: POSITIVO | L7: 45833 | M7: >A3_1_EUKA TGCATGTCTAGTATAAACAGTTTATACTGTGAAACTGCGAATGGCTCATTAAATCAGTTAGAGTTTATTTGATGGTACCACACTACTCGGATAACCGTAGTAAAGCTACAGCTAATACGTGCGTAACTCCCGACTTACGAAGGGACGTATTTATTAGATTCAAGGCCGACCGTGCTTGCACGTCTTTGGTGAATCATGGTAACTTCACGAATCGCAGGGTTTATCCCGGCGATGTTTCATTCAACTTTCTGCCCTATCAACTTTCGACGGTAGTATAGAGGACTACCGTGGTGGTAACGGGTGACGGAGGATTAGGGTTCGATTCCGGAGAGGGAGCCTGAGAAACGGCTACCACATCCAAGGAAGGCAGCAGGCGCGCAAATTACCCAATCCTGACACAGGGAGGTAGTGACAATAAATATCAATTCTGGGCCACATGGTCCGGTAATTGGAATGAGTACAATGTAAACGCCTTAACGAGGATCCATTGGAGGGCAAGTCTGGTGCCAGCAGCCGCGGTAATTCCAGCTCCAATAGCGTATATTTAAGTTGTTGCAGTTAAAAAGCTCGTAGTTGGATTTCGGGTGGGACGCAGCGGTCTCGCATTGCGTTTGTACTGCTGCAGCCCTCCTTCTTGCCGGGGGCGGCCCATCGGACTTCACTGTCTGGGGGTCAGAATCGGCGATGTTACTTTGAGTAAATTAGAGTGTTCAAAGCAAGCTTACGCTCTGAATATAATAGCATGGGATAACACGACAGGACTCTGGCCTATCGTGTTGGTCTATAGGACCAGAGTAATGATTAAGAGGGACAGTCGGGGGCATTCGTATTCCGTTGTCAGAGGTGAAATTCTTGGATTTACGGAAGACGAACATCTGCGAAAGCATTGGCCAAGGATGTTTTCATTGATCAAGAACGAAAGTTGGGGGCTCGAAGACGATAAGATACCGTCGTAGTCTCAACCATAAACGATGCCAACAGGATTGGCGGGGTGTTTTTTTGATGACT | N7: Filogenia
